<?xml version="1.0"?>
<robot name="simple_example">
  <link name="base_link">
    <inertial>
        <mass value="10" />
        <inertia ixx="0.4" ixy="0.0" ixz="0.0" iyy="0.4" iyz="0.0" izz="0.2"/>
    </inertial>
    <collision>
      <geometry>
        <cylinder radius="0.05" length="0.24" />
      </geometry>
        </collision>
    <visual>
      <geometry>
        <cylinder radius="0.05" length="0.24" />
      </geometry>
    </visual>
  </link>

  <link name="second_link">
    <inertial>
        <mass value="0.18" />
        <inertia ixx="0.0002835" ixy="0.0" ixz="0.0" iyy="0.0002835" iyz="0.0" izz="0.000324" />
    </inertial>
    <origin rpy="0.0 0.0 0.0" xyz="0.0 0.0 0.0" />
    <collision>
      <geometry>
        <box size="0.05 0.05 0.15" />
      </geometry>
    </collision>
    <visual>
      <geometry>
        <box size="0.05 0.05 0.15" />
      </geometry>
    </visual>
  </link>

  <joint name="base_to_second_joint" type="continuous">
    <parent link="base_link"/>
    <child link="second_link"/>
    <axis xyz="1 0 0"/>
    <origin xyz="0.0 0.0 0.2" rpy="0.0 0.0 0.0"/> 
  </joint>

  <!--                GAZEBO RELATED PART                             -->

  <!-- ROS Control plugin for Gazebo -->
  <gazebo>
    <plugin name="gazebo_ros_control" filename="libgazebo_ros_control.so">
      <robotNamespace>/simple_model</robotNamespace>
    </plugin>
  </gazebo>

  <!-- transmission -->
  <transmission name="base_to_second_trans">
    <type>transmission_interface/SimpleTransmission</type>
    <actuator name="motor1">
      <mechanicalReduction>1</mechanicalReduction>
    </actuator>
    <joint name="base_to_second_joint">
      <hardwareInterface>EffortJointInterface</hardwareInterface>
    </joint>
  </transmission>
</robot>`
